Workbook

Sheet Assumptions
A1: Stockholm Buy-to-Let Investment Calculator · Assumptions & Inputs
A2: Blue = input | Black = formula | Green = cross-sheet link | Yellow background = key assumption
B4: A · Property & Financing
B5: Purchase Price (SEK) | D5: 3000000 | E5: Source: Hemnet Group Feb 2026
B6: Loan Amount (SEK) | D6: 3500000 | E6: Exceeds purchase price → high LTV; review
B7: Equity / Down-payment (SEK) | D7: =D6-D5 -> 500000 | E7: Auto-calculated
B8: Loan-to-Value (LTV) | D8: =D6/D5 -> 1.1666667 | E8: Swedish banks typically cap at 85%
B9: Loan Term (years) | D9: 30 | E9: Adjust for amortisation scenario
B10: Interest Rate – Base Case (%) | D10: 0.025 | E10: Riksbank benchmark; source: Riksbank Mar 2026
B11: Interest Rate – Stress Case (%) | D11: 0.045 | E11: Elevated scenario (+200 bps)
B12: Annual Principal Amortisation Rate (%) | D12: 0.02 | E12: Typical Swedish amorteringskrav (2% on LTV > 70%)
B14: B · Rental Income
B15: Starting Monthly Rent – Low (SEK) | D15: 12000 | E15: Low market scenario; Qasa/Blocket 2025
B16: Starting Monthly Rent – Mid (SEK) | D16: 14500 | E16: Mid scenario; SvD / Qasa 2025
B17: Starting Monthly Rent – High (SEK) | D17: 17000 | E17: High / central Stockholm benchmark
B18: Annual Rent Growth Rate (%) | D18: 0.03 | E18: CPI-linked; Swedish avg. 2015-2024 ≈ 3%
B19: Vacancy Allowance (% of gross rent) | D19: 0.05 | E19: 5% vacancy assumed (≈ 0.6 months/year)
B20: Annual Rent – Mid (SEK) | D20: =D16*12 -> 174000 | E20: Auto
B22: C · Annual Operating Costs
B23: BRF Fee (SEK/month) | D23: 2000 | E23: HSB Stockholm BRF Barometer 2025 (~833 SEK/sqm/yr)
B24: Maintenance Reserve (SEK/year) | D24: 6000 | E24: ~0.2% of property value; adjust to taste
B25: Property Insurance (SEK/year) | D25: 3600 | E25: Estimate; obtain actual quote
B26: Letting / Management Fee (% of rent) | D26: 0.08 | E26: Typical Swedish letting agent 8-10%
B27: Other Annual Costs (SEK) | D27: 0 | E27: E.g. council tax, unexpected repairs
B28: Total Annual OpEx – Mid (SEK) | D28: =D23*12+D24+D25+D16*12*D26+D27 -> 47520 | E28: Sum of above at mid rent
B30: D · Tax Assumptions (Sweden)
B31: Capital Gains Tax Rate on Sale (%) | D31: 0.22 | E31: Swedish reavinstskatt on bostadsrätt = 22%
B32: Rental Income Tax Rate (%) | D32: 0.3 | E32: Standard marginal rate; consult skatteverket
B33: Annual Schablonavdrag (SEK) | D33: 40000 | E33: Standard deduction on rental income
B35: E · Market & Exit Assumptions
B36: Apartment Size (sqm) | D36: =D5/72000 -> 41.666667 | E36: Implied from purchase price & Stockholm avg. 72,000 SEK/sqm
B37: Annual Property Appreciation (%) | D37: 0.03 | E37: Stockholm apt. long-run real appreciation ~2-3%
B38: Holding Period (years) | D38: 10 | E38: Used in total return & exit value calc
B39: Exit Sale Costs (% of sale price) | D39: 0.025 | E39: Agent fee ~2.5%
B40: Estimated Exit Value (SEK) | D40: =D5*(1+D37)^D38 -> 4031749.1 | E40: Auto-calculated
B41: Net Proceeds After Agent Fee (SEK) | D41: =D40*(1-D39) -> 3930955.4 | E41: Auto-calculated
B42: Capital Gain (SEK) | D42: =D41-D5 -> 930955.41 | E42: Gross gain; tax below
B43: Tax on Capital Gain (SEK) | D43: =MAX(0,D42)*D31 -> 204810.19 | E43: 22% reavinstskatt if gain > 0
B44: After-Tax Capital Gain (SEK) | D44: =D42-D43 -> 726145.22 | E44: Net equity release on exit

Sheet Annual_Cashflow
A1: Annual Cash-Flow Model · 10-Year Projection (Mid-Rent Scenario @ Base Interest Rate)
A2: All figures in SEK. Formulas reference Assumptions sheet. Sensitivity scenarios on 'Sensitivity' tab.
B4: Year | C4: Gross Rent (SEK/yr) | D4: Vacancy Loss | E4: Net Rent (SEK/yr) | F4: Annual Interest | G4: Principal Amort. | H4: BRF Fee (SEK/yr) | I4: Mgmt Fee (SEK/yr) | J4: Maint. + Insurance | K4: Total OpEx | L4: Pre-Tax Cash Profit | M4: Tax on Rent | N4: After-Tax Cash Profit
B5: 1 | C5: =Assumptions!D16*(1+Assumptions!D18)^(1-1)*12 -> 174000 | D5: =-B5*Assumptions!D19 -> -0.05 | E5: =B5+C5 -> 174001 | F5: =-3500000*Assumptions!D10 -> -87500 | G5: =-3500000*(1-Assumptions!D12)^(1-1)*Assumptions!D12 -> -70000 | H5: =-Assumptions!D23*12 -> -24000 | I5: =-Assumptions!D16*(1+Assumptions!D18)^(1-1)*12*Assumptions!D26 -> -13920 | J5: =-(Assumptions!D24+Assumptions!D25) -> -9600 | K5: =E5+F5+G5+H5+I5 -> -21419 | L5: =D5+J5 -> -9600.05 | M5: =IF(D5-Assumptions!D33>0,-(D5-Assumptions!D33)*Assumptions!D32,0) -> 0 | N5: =K5+L5 -> -31019.05
B6: 2 | C6: =Assumptions!D16*(1+Assumptions!D18)^(2-1)*12 -> 179220 | D6: =-B6*Assumptions!D19 -> -0.1 | E6: =B6+C6 -> 179222 | F6: =-((3500000*(1-Assumptions!D12)^(2-1)))*Assumptions!D10 -> -85750 | G6: =-3500000*(1-Assumptions!D12)^(2-1)*Assumptions!D12 -> -68600 | H6: =-Assumptions!D23*12 -> -24000 | I6: =-Assumptions!D16*(1+Assumptions!D18)^(2-1)*12*Assumptions!D26 -> -14337.6 | J6: =-(Assumptions!D24+Assumptions!D25) -> -9600 | K6: =E6+F6+G6+H6+I6 -> -13465.6 | L6: =D6+J6 -> -9600.1 | M6: =IF(D6-Assumptions!D33>0,-(D6-Assumptions!D33)*Assumptions!D32,0) -> 0 | N6: =K6+L6 -> -23065.7
B7: 3 | C7: =Assumptions!D16*(1+Assumptions!D18)^(3-1)*12 -> 184596.6 | D7: =-B7*Assumptions!D19 -> -0.15 | E7: =B7+C7 -> 184599.6 | F7: =-((3500000*(1-Assumptions!D12)^(3-1)))*Assumptions!D10 -> -84035 | G7: =-3500000*(1-Assumptions!D12)^(3-1)*Assumptions!D12 -> -67228 | H7: =-Assumptions!D23*12 -> -24000 | I7: =-Assumptions!D16*(1+Assumptions!D18)^(3-1)*12*Assumptions!D26 -> -14767.728 | J7: =-(Assumptions!D24+Assumptions!D25) -> -9600 | K7: =E7+F7+G7+H7+I7 -> -5431.128 | L7: =D7+J7 -> -9600.15 | M7: =IF(D7-Assumptions!D33>0,-(D7-Assumptions!D33)*Assumptions!D32,0) -> 0 | N7: =K7+L7 -> -15031.278
B8: 4 | C8: =Assumptions!D16*(1+Assumptions!D18)^(4-1)*12 -> 190134.5 | D8: =-B8*Assumptions!D19 -> -0.2 | E8: =B8+C8 -> 190138.5 | F8: =-((3500000*(1-Assumptions!D12)^(4-1)))*Assumptions!D10 -> -82354.3 | G8: =-3500000*(1-Assumptions!D12)^(4-1)*Assumptions!D12 -> -65883.44 | H8: =-Assumptions!D23*12 -> -24000 | I8: =-Assumptions!D16*(1+Assumptions!D18)^(4-1)*12*Assumptions!D26 -> -15210.76 | J8: =-(Assumptions!D24+Assumptions!D25) -> -9600 | K8: =E8+F8+G8+H8+I8 -> 2689.9982 | L8: =D8+J8 -> -9600.2 | M8: =IF(D8-Assumptions!D33>0,-(D8-Assumptions!D33)*Assumptions!D32,0) -> 0 | N8: =K8+L8 -> -6910.2018
B9: 5 | C9: =Assumptions!D16*(1+Assumptions!D18)^(5-1)*12 -> 195838.53 | D9: =-B9*Assumptions!D19 -> -0.25 | E9: =B9+C9 -> 195843.53 | F9: =-((3500000*(1-Assumptions!D12)^(5-1)))*Assumptions!D10 -> -80707.214 | G9: =-3500000*(1-Assumptions!D12)^(5-1)*Assumptions!D12 -> -64565.771 | H9: =-Assumptions!D23*12 -> -24000 | I9: =-Assumptions!D16*(1+Assumptions!D18)^(5-1)*12*Assumptions!D26 -> -15667.083 | J9: =-(Assumptions!D24+Assumptions!D25) -> -9600 | K9: =E9+F9+G9+H9+I9 -> 10903.465 | L9: =D9+J9 -> -9600.25 | M9: =IF(D9-Assumptions!D33>0,-(D9-Assumptions!D33)*Assumptions!D32,0) -> 0 | N9: =K9+L9 -> 1303.2151
B10: 6 | C10: =Assumptions!D16*(1+Assumptions!D18)^(6-1)*12 -> 201713.69 | D10: =-B10*Assumptions!D19 -> -0.3 | E10: =B10+C10 -> 201719.69 | F10: =-((3500000*(1-Assumptions!D12)^(6-1)))*Assumptions!D10 -> -79093.07 | G10: =-3500000*(1-Assumptions!D12)^(6-1)*Assumptions!D12 -> -63274.456 | H10: =-Assumptions!D23*12 -> -24000 | I10: =-Assumptions!D16*(1+Assumptions!D18)^(6-1)*12*Assumptions!D26 -> -16137.095 | J10: =-(Assumptions!D24+Assumptions!D25) -> -9600 | K10: =E10+F10+G10+H10+I10 -> 19215.068 | L10: =D10+J10 -> -9600.3 | M10: =IF(D10-Assumptions!D33>0,-(D10-Assumptions!D33)*Assumptions!D32,0) -> 0 | N10: =K10+L10 -> 9614.7683
B11: 7 | C11: =Assumptions!D16*(1+Assumptions!D18)^(7-1)*12 -> 207765.1 | D11: =-B11*Assumptions!D19 -> -0.35 | E11: =B11+C11 -> 207772.1 | F11: =-((3500000*(1-Assumptions!D12)^(7-1)))*Assumptions!D10 -> -77511.208 | G11: =-3500000*(1-Assumptions!D12)^(7-1)*Assumptions!D12 -> -62008.967 | H11: =-Assumptions!D23*12 -> -24000 | I11: =-Assumptions!D16*(1+Assumptions!D18)^(7-1)*12*Assumptions!D26 -> -16621.208 | J11: =-(Assumptions!D24+Assumptions!D25) -> -9600 | K11: =E11+F11+G11+H11+I11 -> 27630.717 | L11: =D11+J11 -> -9600.35 | M11: =IF(D11-Assumptions!D33>0,-(D11-Assumptions!D33)*Assumptions!D32,0) -> 0 | N11: =K11+L11 -> 18030.367
B12: 8 | C12: =Assumptions!D16*(1+Assumptions!D18)^(8-1)*12 -> 213998.05 | D12: =-B12*Assumptions!D19 -> -0.4 | E12: =B12+C12 -> 214006.05 | F12: =-((3500000*(1-Assumptions!D12)^(8-1)))*Assumptions!D10 -> -75960.984 | G12: =-3500000*(1-Assumptions!D12)^(8-1)*Assumptions!D12 -> -60768.787 | H12: =-Assumptions!D23*12 -> -24000 | I12: =-Assumptions!D16*(1+Assumptions!D18)^(8-1)*12*Assumptions!D26 -> -17119.844 | J12: =-(Assumptions!D24+Assumptions!D25) -> -9600 | K12: =E12+F12+G12+H12+I12 -> 36156.437 | L12: =D12+J12 -> -9600.4 | M12: =IF(D12-Assumptions!D33>0,-(D12-Assumptions!D33)*Assumptions!D32,0) -> 0 | N12: =K12+L12 -> 26556.037
B13: 9 | C13: =Assumptions!D16*(1+Assumptions!D18)^(9-1)*12 -> 220417.99 | D13: =-B13*Assumptions!D19 -> -0.45 | E13: =B13+C13 -> 220426.99 | F13: =-((3500000*(1-Assumptions!D12)^(9-1)))*Assumptions!D10 -> -74441.764 | G13: =-3500000*(1-Assumptions!D12)^(9-1)*Assumptions!D12 -> -59553.412 | H13: =-Assumptions!D23*12 -> -24000 | I13: =-Assumptions!D16*(1+Assumptions!D18)^(9-1)*12*Assumptions!D26 -> -17633.44 | J13: =-(Assumptions!D24+Assumptions!D25) -> -9600 | K13: =E13+F13+G13+H13+I13 -> 44798.379 | L13: =D13+J13 -> -9600.45 | M13: =IF(D13-Assumptions!D33>0,-(D13-Assumptions!D33)*Assumptions!D32,0) -> 0 | N13: =K13+L13 -> 35197.929
B14: 10 | C14: =Assumptions!D16*(1+Assumptions!D18)^(10-1)*12 -> 227030.53 | D14: =-B14*Assumptions!D19 -> -0.5 | E14: =B14+C14 -> 227040.53 | F14: =-((3500000*(1-Assumptions!D12)^(10-1)))*Assumptions!D10 -> -72952.929 | G14: =-3500000*(1-Assumptions!D12)^(10-1)*Assumptions!D12 -> -58362.343 | H14: =-Assumptions!D23*12 -> -24000 | I14: =-Assumptions!D16*(1+Assumptions!D18)^(10-1)*12*Assumptions!D26 -> -18162.443 | J14: =-(Assumptions!D24+Assumptions!D25) -> -9600 | K14: =E14+F14+G14+H14+I14 -> 53562.819 | L14: =D14+J14 -> -9600.5 | M14: =IF(D14-Assumptions!D33>0,-(D14-Assumptions!D33)*Assumptions!D32,0) -> 0 | N14: =K14+L14 -> 43962.319
B15: 10-Year Totals | C15: =SUM(C5:C14) -> 1994715 | D15: =SUM(D5:D14) -> -2.75 | E15: =SUM(E5:E14) -> 1994770 | F15: =SUM(F5:F14) -> -800306.47 | G15: =SUM(G5:G14) -> -640245.18 | H15: =SUM(H5:H14) -> -240000 | I15: =SUM(I5:I14) -> -159577.2 | J15: =SUM(J5:J14) -> -96000 | ... M15: =SUM(M5:M14) -> 0
B17: Key Metrics (Mid Rent / Base Rate)
B18: Gross Yield (%) | D18: =Assumptions!D16*12/Assumptions!D5 -> 0.058
B19: Net Yield – pre-tax (%) | D19: =(Assumptions!D16*12*(1-Assumptions!D19)-Assumptions!D28)/Assumptions!D5 -> 0.03926
B20: Debt Service Coverage Ratio | D20: =(Assumptions!D16*12*(1-Assumptions!D19))/((Assumptions!D6*Assumptions!D10)+(Assumptions!D6*Assumptions!D12)) -> 1.0495238
B21: Annual After-Tax Profit Yr 1 | D21: =M5 -> 0
B22: 10-Year Cumulative After-Tax | D22: =M15 -> 0

Sheet Sensitivity
A1: Sensitivity Analysis · Annual After-Tax Cash Profit (SEK/year) · Year 1
B4: Rent ↓ / Rate → | C4: 2.5% (Base) | D4: 3.5% (Mid) | E4: 4.5% (Stress)
B5: Low (12,000) | C5: -94860 | D5: -129860 | E5: -164860
B6: Mid (14,500) | C6: -77310 | D6: -112310 | E6: -147310
B7: High (17,000) | C7: -59760 | D7: -94760 | E7: -129760
B9: Note: Values are hardcoded Year-1 estimates using model assumptions. Green = positive cashflow; amber = marginal; red = negative.
B11: Break-Even Rent (SEK/month) Required to Cover All Costs
B13: Interest Rate | C13: Break-Even Rent (SEK/mo) | D13: Break-Even vs. Mid Market
B14: 2.5% (Base) | C14: 18220.824 | D14: 3720.8238
B15: 3.5% (Mid) | C15: 21557.971 | D15: 7057.971
B16: 4.5% (Stress) | C16: 24895.118 | D16: 10395.118

Sheet Total_Return
A1: Total Return Analysis · 10-Year Hold · Mid Rent / Base Rate
B3: INCOME RETURN
B4: Cumulative After-Tax Cash Profit (10 yrs) | E4: =Annual_Cashflow!M15 -> 0
B6: CAPITAL RETURN
B7: Estimated Exit Value (SEK) | E7: =Assumptions!D40 -> 4031749.1
B8: Less: Agent Fee | E8: =-Assumptions!D40*Assumptions!D39 -> -100793.73
B9: Less: Outstanding Loan Balance | E9: =-3500000*(1-0.02)^10 -> -2859754.8
B10: Less: Tax on Capital Gain | E10: =-Assumptions!D43 -> -204810.19
B11: Net Capital Proceeds | E11: =E5+E6+E7+E8 -> 3930955.4
B12: Initial Equity Invested | E12: =-Assumptions!D7 -> -500000
B13: Net Capital Gain on Equity | E13: =E9+E10 -> -3064565
B15: TOTAL RETURN (SEK) | E15: =E2+E11 -> 3930955.4
B16: Equity Multiple (x) | E16: =(E2+E9)/(-E10) -> -13.962952
B17: Annualised Return on Equity (IRR approx) | E17: =(1+E14)^(1/10)-1 -> 0

Sheet Loan_Paydown
A1: Loan Paydown Schedule · 180-Month Amortisation · Base Rate
B3: Month | C3: Year | D3: Opening Balance (SEK) | E3: Interest (SEK) | F3: Principal (SEK) | G3: Total Payment (SEK) | H3: Closing Balance (SEK) | I3: Cum. Interest (SEK) | J3: Cum. Principal (SEK)
B4: 1 | C4: 1 | D4: =Assumptions!D6 -> 3500000 | E4: =D4*Assumptions!D10/12 -> 7291.6667 | F4: =Assumptions!D6*Assumptions!D12/12 -> 5833.3333 | G4: =E4+F4 -> 13125 | H4: =D4-F4 -> 3494166.7 | I4: =E4 -> 7291.6667 | J4: =F4 -> 5833.3333
B5: 2 | C5: 1 | D5: =H4 -> 3494166.7 | E5: =D5*Assumptions!D10/12 -> 7279.5139 | F5: =Assumptions!D6*Assumptions!D12/12 -> 5833.3333 | G5: =E5+F5 -> 13112.847 | H5: =D5-F5 -> 3488333.3 | I5: =I4+E5 -> 14571.181 | J5: =J4+F5 -> 11666.667
B6: 3 | C6: 1 | D6: =H5 -> 3488333.3 | E6: =D6*Assumptions!D10/12 -> 7267.3611 | F6: =Assumptions!D6*Assumptions!D12/12 -> 5833.3333 | G6: =E6+F6 -> 13100.694 | H6: =D6-F6 -> 3482500 | I6: =I5+E6 -> 21838.542 | J6: =J5+F6 -> 17500
B7: 4 | C7: 1 | D7: =H6 -> 3482500 | E7: =D7*Assumptions!D10/12 -> 7255.2083 | F7: =Assumptions!D6*Assumptions!D12/12 -> 5833.3333 | G7: =E7+F7 -> 13088.542 | H7: =D7-F7 -> 3476666.7 | I7: =I6+E7 -> 29093.75 | J7: =J6+F7 -> 23333.333
B8: 5 | C8: 1 | D8: =H7 -> 3476666.7 | E8: =D8*Assumptions!D10/12 -> 7243.0556 | F8: =Assumptions!D6*Assumptions!D12/12 -> 5833.3333 | G8: =E8+F8 -> 13076.389 | H8: =D8-F8 -> 3470833.3 | I8: =I7+E8 -> 36336.806 | J8: =J7+F8 -> 29166.667
B9: 6 | C9: 1 | D9: =H8 -> 3470833.3 | E9: =D9*Assumptions!D10/12 -> 7230.9028 | F9: =Assumptions!D6*Assumptions!D12/12 -> 5833.3333 | G9: =E9+F9 -> 13064.236 | H9: =D9-F9 -> 3465000 | I9: =I8+E9 -> 43567.708 | J9: =J8+F9 -> 35000
B10: 7 | C10: 1 | D10: =H9 -> 3465000 | E10: =D10*Assumptions!D10/12 -> 7218.75 | F10: =Assumptions!D6*Assumptions!D12/12 -> 5833.3333 | G10: =E10+F10 -> 13052.083 | H10: =D10-F10 -> 3459166.7 | I10: =I9+E10 -> 50786.458 | J10: =J9+F10 -> 40833.333
B11: 8 | C11: 1 | D11: =H10 -> 3459166.7 | E11: =D11*Assumptions!D10/12 -> 7206.5972 | F11: =Assumptions!D6*Assumptions!D12/12 -> 5833.3333 | G11: =E11+F11 -> 13039.931 | H11: =D11-F11 -> 3453333.3 | I11: =I10+E11 -> 57993.056 | J11: =J10+F11 -> 46666.667
B12: 9 | C12: 1 | D12: =H11 -> 3453333.3 | E12: =D12*Assumptions!D10/12 -> 7194.4444 | F12: =Assumptions!D6*Assumptions!D12/12 -> 5833.3333 | G12: =E12+F12 -> 13027.778 | H12: =D12-F12 -> 3447500 | I12: =I11+E12 -> 65187.5 | J12: =J11+F12 -> 52500
B13: 10 | C13: 1 | D13: =H12 -> 3447500 | E13: =D13*Assumptions!D10/12 -> 7182.2917 | F13: =Assumptions!D6*Assumptions!D12/12 -> 5833.3333 | G13: =E13+F13 -> 13015.625 | H13: =D13-F13 -> 3441666.7 | I13: =I12+E13 -> 72369.792 | J13: =J12+F13 -> 58333.333
B14: 11 | C14: 1 | D14: =H13 -> 3441666.7 | E14: =D14*Assumptions!D10/12 -> 7170.1389 | F14: =Assumptions!D6*Assumptions!D12/12 -> 5833.3333 | G14: =E14+F14 -> 13003.472 | H14: =D14-F14 -> 3435833.3 | I14: =I13+E14 -> 79539.931 | J14: =J13+F14 -> 64166.667
B15: 12 | C15: 1 | D15: =H14 -> 3435833.3 | E15: =D15*Assumptions!D10/12 -> 7157.9861 | F15: =Assumptions!D6*Assumptions!D12/12 -> 5833.3333 | G15: =E15+F15 -> 12991.319 | H15: =D15-F15 -> 3430000 | I15: =I14+E15 -> 86697.917 | J15: =J14+F15 -> 70000
B16: 13 | C16: 2 | D16: =H15 -> 3430000 | E16: =D16*Assumptions!D10/12 -> 7145.8333 | F16: =Assumptions!D6*Assumptions!D12/12 -> 5833.3333 | G16: =E16+F16 -> 12979.167 | H16: =D16-F16 -> 3424166.7 | I16: =I15+E16 -> 93843.75 | J16: =J15+F16 -> 75833.333
B17: 14 | C17: 2 | D17: =H16 -> 3424166.7 | E17: =D17*Assumptions!D10/12 -> 7133.6806 | F17: =Assumptions!D6*Assumptions!D12/12 -> 5833.3333 | G17: =E17+F17 -> 12967.014 | H17: =D17-F17 -> 3418333.3 | I17: =I16+E17 -> 100977.43 | J17: =J16+F17 -> 81666.667
B18: 15 | C18: 2 | D18: =H17 -> 3418333.3 | E18: =D18*Assumptions!D10/12 -> 7121.5278 | F18: =Assumptions!D6*Assumptions!D12/12 -> 5833.3333 | G18: =E18+F18 -> 12954.861 | H18: =D18-F18 -> 3412500 | I18: =I17+E18 -> 108098.96 | J18: =J17+F18 -> 87500
B19: 16 | C19: 2 | D19: =H18 -> 3412500 | E19: =D19*Assumptions!D10/12 -> 7109.375 | F19: =Assumptions!D6*Assumptions!D12/12 -> 5833.3333 | G19: =E19+F19 -> 12942.708 | H19: =D19-F19 -> 3406666.7 | I19: =I18+E19 -> 115208.33 | J19: =J18+F19 -> 93333.333
B20: 17 | C20: 2 | D20: =H19 -> 3406666.7 | E20: =D20*Assumptions!D10/12 -> 7097.2222 | F20: =Assumptions!D6*Assumptions!D12/12 -> 5833.3333 | G20: =E20+F20 -> 12930.556 | H20: =D20-F20 -> 3400833.3 | I20: =I19+E20 -> 122305.56 | J20: =J19+F20 -> 99166.667
B21: 18 | C21: 2 | D21: =H20 -> 3400833.3 | E21: =D21*Assumptions!D10/12 -> 7085.0694 | F21: =Assumptions!D6*Assumptions!D12/12 -> 5833.3333 | G21: =E21+F21 -> 12918.403 | H21: =D21-F21 -> 3395000 | I21: =I20+E21 -> 129390.62 | J21: =J20+F21 -> 105000
B22: 19 | C22: 2 | D22: =H21 -> 3395000 | E22: =D22*Assumptions!D10/12 -> 7072.9167 | F22: =Assumptions!D6*Assumptions!D12/12 -> 5833.3333 | G22: =E22+F22 -> 12906.25 | H22: =D22-F22 -> 3389166.7 | I22: =I21+E22 -> 136463.54 | J22: =J21+F22 -> 110833.33
B23: 20 | C23: 2 | D23: =H22 -> 3389166.7 | E23: =D23*Assumptions!D10/12 -> 7060.7639 | F23: =Assumptions!D6*Assumptions!D12/12 -> 5833.3333 | G23: =E23+F23 -> 12894.097 | H23: =D23-F23 -> 3383333.3 | I23: =I22+E23 -> 143524.31 | J23: =J22+F23 -> 116666.67
B24: 21 | C24: 2 | D24: =H23 -> 3383333.3 | E24: =D24*Assumptions!D10/12 -> 7048.6111 | F24: =Assumptions!D6*Assumptions!D12/12 -> 5833.3333 | G24: =E24+F24 -> 12881.944 | H24: =D24-F24 -> 3377500 | I24: =I23+E24 -> 150572.92 | J24: =J23+F24 -> 122500
B25: 22 | C25: 2 | D25: =H24 -> 3377500 | E25: =D25*Assumptions!D10/12 -> 7036.4583 | F25: =Assumptions!D6*Assumptions!D12/12 -> 5833.3333 | G25: =E25+F25 -> 12869.792 | H25: =D25-F25 -> 3371666.7 | I25: =I24+E25 -> 157609.38 | J25: =J24+F25 -> 128333.33
B26: 23 | C26: 2 | D26: =H25 -> 3371666.7 | E26: =D26*Assumptions!D10/12 -> 7024.3056 | F26: =Assumptions!D6*Assumptions!D12/12 -> 5833.3333 | G26: =E26+F26 -> 12857.639 | H26: =D26-F26 -> 3365833.3 | I26: =I25+E26 -> 164633.68 | J26: =J25+F26 -> 134166.67
B27: 24 | C27: 2 | D27: =H26 -> 3365833.3 | E27: =D27*Assumptions!D10/12 -> 7012.1528 | F27: =Assumptions!D6*Assumptions!D12/12 -> 5833.3333 | G27: =E27+F27 -> 12845.486 | H27: =D27-F27 -> 3360000 | I27: =I26+E27 -> 171645.83 | J27: =J26+F27 -> 140000
B28: 25 | C28: 3 | D28: =H27 -> 3360000 | E28: =D28*Assumptions!D10/12 -> 7000 | F28: =Assumptions!D6*Assumptions!D12/12 -> 5833.3333 | G28: =E28+F28 -> 12833.333 | H28: =D28-F28 -> 3354166.7 | I28: =I27+E28 -> 178645.83 | J28: =J27+F28 -> 145833.33
B29: 26 | C29: 3 | D29: =H28 -> 3354166.7 | E29: =D29*Assumptions!D10/12 -> 6987.8472 | F29: =Assumptions!D6*Assumptions!D12/12 -> 5833.3333 | G29: =E29+F29 -> 12821.181 | H29: =D29-F29 -> 3348333.3 | I29: =I28+E29 -> 185633.68 | J29: =J28+F29 -> 151666.67
B30: 27 | C30: 3 | D30: =H29 -> 3348333.3 | E30: =D30*Assumptions!D10/12 -> 6975.6944 | F30: =Assumptions!D6*Assumptions!D12/12 -> 5833.3333 | G30: =E30+F30 -> 12809.028 | H30: =D30-F30 -> 3342500 | I30: =I29+E30 -> 192609.38 | J30: =J29+F30 -> 157500
B31: 28 | C31: 3 | D31: =H30 -> 3342500 | E31: =D31*Assumptions!D10/12 -> 6963.5417 | F31: =Assumptions!D6*Assumptions!D12/12 -> 5833.3333 | G31: =E31+F31 -> 12796.875 | H31: =D31-F31 -> 3336666.7 | I31: =I30+E31 -> 199572.92 | J31: =J30+F31 -> 163333.33
B32: 29 | C32: 3 | D32: =H31 -> 3336666.7 | E32: =D32*Assumptions!D10/12 -> 6951.3889 | F32: =Assumptions!D6*Assumptions!D12/12 -> 5833.3333 | G32: =E32+F32 -> 12784.722 | H32: =D32-F32 -> 3330833.3 | I32: =I31+E32 -> 206524.31 | J32: =J31+F32 -> 169166.67
B33: 30 | C33: 3 | D33: =H32 -> 3330833.3 | E33: =D33*Assumptions!D10/12 -> 6939.2361 | F33: =Assumptions!D6*Assumptions!D12/12 -> 5833.3333 | G33: =E33+F33 -> 12772.569 | H33: =D33-F33 -> 3325000 | I33: =I32+E33 -> 213463.54 | J33: =J32+F33 -> 175000
B34: 31 | C34: 3 | D34: =H33 -> 3325000 | E34: =D34*Assumptions!D10/12 -> 6927.0833 | F34: =Assumptions!D6*Assumptions!D12/12 -> 5833.3333 | G34: =E34+F34 -> 12760.417 | H34: =D34-F34 -> 3319166.7 | I34: =I33+E34 -> 220390.62 | J34: =J33+F34 -> 180833.33
B35: 32 | C35: 3 | D35: =H34 -> 3319166.7 | E35: =D35*Assumptions!D10/12 -> 6914.9306 | F35: =Assumptions!D6*Assumptions!D12/12 -> 5833.3333 | G35: =E35+F35 -> 12748.264 | H35: =D35-F35 -> 3313333.3 | I35: =I34+E35 -> 227305.56 | J35: =J34+F35 -> 186666.67
B36: 33 | C36: 3 | D36: =H35 -> 3313333.3 | E36: =D36*Assumptions!D10/12 -> 6902.7778 | F36: =Assumptions!D6*Assumptions!D12/12 -> 5833.3333 | G36: =E36+F36 -> 12736.111 | H36: =D36-F36 -> 3307500 | I36: =I35+E36 -> 234208.33 | J36: =J35+F36 -> 192500
B37: 34 | C37: 3 | D37: =H36 -> 3307500 | E37: =D37*Assumptions!D10/12 -> 6890.625 | F37: =Assumptions!D6*Assumptions!D12/12 -> 5833.3333 | G37: =E37+F37 -> 12723.958 | H37: =D37-F37 -> 3301666.7 | I37: =I36+E37 -> 241098.96 | J37: =J36+F37 -> 198333.33
B38: 35 | C38: 3 | D38: =H37 -> 3301666.7 | E38: =D38*Assumptions!D10/12 -> 6878.4722 | F38: =Assumptions!D6*Assumptions!D12/12 -> 5833.3333 | G38: =E38+F38 -> 12711.806 | H38: =D38-F38 -> 3295833.3 | I38: =I37+E38 -> 247977.43 | J38: =J37+F38 -> 204166.67
B39: 36 | C39: 3 | D39: =H38 -> 3295833.3 | E39: =D39*Assumptions!D10/12 -> 6866.3194 | F39: =Assumptions!D6*Assumptions!D12/12 -> 5833.3333 | G39: =E39+F39 -> 12699.653 | H39: =D39-F39 -> 3290000 | I39: =I38+E39 -> 254843.75 | J39: =J38+F39 -> 210000
B40: 37 | C40: 4 | D40: =H39 -> 3290000 | E40: =D40*Assumptions!D10/12 -> 6854.1667 | F40: =Assumptions!D6*Assumptions!D12/12 -> 5833.3333 | G40: =E40+F40 -> 12687.5 | H40: =D40-F40 -> 3284166.7 | I40: =I39+E40 -> 261697.92 | J40: =J39+F40 -> 215833.33
B41: 38 | C41: 4 | D41: =H40 -> 3284166.7 | E41: =D41*Assumptions!D10/12 -> 6842.0139 | F41: =Assumptions!D6*Assumptions!D12/12 -> 5833.3333 | G41: =E41+F41 -> 12675.347 | H41: =D41-F41 -> 3278333.3 | I41: =I40+E41 -> 268539.93 | J41: =J40+F41 -> 221666.67
...

Sheet Market_Context
A1: Stockholm Market Benchmarks & Regulatory Context
B3: Metric | C3: Value | D3: Unit | E3: Notes / Source
B4: Avg. apt price – Greater Stockholm | C4: 72,000 | D4: SEK/sqm | E4: Hemnet Group, Feb 2026
B5: Avg. apt price – Inner City | C5: 105,000–130,000 | D5: SEK/sqm | E5: Mäklarstatistik, Q4 2025
B6: Market rent – Low | C6: 12,000 | D6: SEK/mo | E6: Blocket/Qasa entry-level, 2025
B7: Market rent – Mid | C7: 14,500 | D7: SEK/mo | E7: Qasa midpoint, SvD 2025
B8: Market rent – High | C8: 17,000 | D8: SEK/mo | E8: Central Stockholm premium, 2025
B9: Average BRF fee | C9: 833 | D9: SEK/sqm/yr | E9: HSB BRF Barometer 2025
B10: Riksbank policy rate | C10: 2.25% | E10: Riksbank, March 2026 (approx.)
B11: Swedish mortgage rate (avg) | C11: 3.5–4.0% | E11: SCB, Q1 2026
B12: Capital gains tax (bostadsrätt) | C12: 22% | E12: Skatteverket reavinstskatt
B13: Schablonavdrag (rental deduction) | C13: 40,000 | D13: SEK/yr | E13: Skatteverket 2026
B14: Amorteringskrav (LTV > 70%) | C14: 2%/yr | E14: Finansinspektionen 2024
B15: Amorteringskrav (LTV > 85%) | C15: 3%/yr | E15: Finansinspektionen 2024
B16: Stämpelskatt (stamp duty) | C16: 1.5% | D16: of price | E16: On bostadsrätt purchase
B17: Long-run apt. price growth | C17: 2–3% | D17: %/yr | E17: Riksbank/SEB historical nominal
